{"trial_id": "01", "hyperparameters": {"space": [{"class_name": "Int", "config": {"name": "num_layers", "default": null, "conditions": [], "min_value": 5, "max_value": 40, "step": 5, "sampling": "linear"}}, {"class_name": "Int", "config": {"name": "num_neurons", "default": null, "conditions": [], "min_value": 40, "max_value": 360, "step": 20, "sampling": "linear"}}], "values": {"num_layers": 5, "num_neurons": 60}}, "metrics": {"metrics": {}}, "score": null, "best_step": 0, "status": "FAILED", "message": "Traceback (most recent call last):\n  File \"/Users/tupho/miniconda3/lib/python3.11/site-packages/keras_tuner/src/engine/base_tuner.py\", line 274, in _try_run_and_update_trial\n    self._run_and_update_trial(trial, *fit_args, **fit_kwargs)\n  File \"/Users/tupho/miniconda3/lib/python3.11/site-packages/keras_tuner/src/engine/base_tuner.py\", line 239, in _run_and_update_trial\n    results = self.run_trial(trial, *fit_args, **fit_kwargs)\n              ^^^^^^^^^^^^^^^^^^^^^^^^^^^^^^^^^^^^^^^^^^^^^^\n  File \"/Users/tupho/miniconda3/lib/python3.11/site-packages/keras_tuner/src/engine/tuner.py\", line 314, in run_trial\n    obj_value = self._build_and_fit_model(trial, *args, **copied_kwargs)\n                ^^^^^^^^^^^^^^^^^^^^^^^^^^^^^^^^^^^^^^^^^^^^^^^^^^^^^^^^\n  File \"/Users/tupho/miniconda3/lib/python3.11/site-packages/keras_tuner/src/engine/tuner.py\", line 233, in _build_and_fit_model\n    results = self.hypermodel.fit(hp, model, *args, **kwargs)\n              ^^^^^^^^^^^^^^^^^^^^^^^^^^^^^^^^^^^^^^^^^^^^^^^\n  File \"/Users/tupho/miniconda3/lib/python3.11/site-packages/keras_tuner/src/engine/hypermodel.py\", line 149, in fit\n    return model.fit(*args, **kwargs)\n           ^^^^^^^^^^^^^^^^^^^^^^^^^^\n  File \"/Users/tupho/miniconda3/lib/python3.11/site-packages/keras/src/utils/traceback_utils.py\", line 122, in error_handler\n    raise e.with_traceback(filtered_tb) from None\n  File \"/Users/tupho/miniconda3/lib/python3.11/site-packages/tensorflow/python/eager/execute.py\", line 59, in quick_execute\n    except TypeError as e:\ntensorflow.python.framework.errors_impl.InvalidArgumentError: Graph execution error:\n\nDetected at node functional_18_1/X20_subnetwork_1/dense_96_1/Add defined at (most recent call last):\n  File \"<frozen runpy>\", line 198, in _run_module_as_main\n\n  File \"<frozen runpy>\", line 88, in _run_code\n\n  File \"/Users/tupho/miniconda3/lib/python3.11/site-packages/ipykernel_launcher.py\", line 17, in <module>\n\n  File \"/Users/tupho/miniconda3/lib/python3.11/site-packages/traitlets/config/application.py\", line 1075, in launch_instance\n\n  File \"/Users/tupho/miniconda3/lib/python3.11/site-packages/ipykernel/kernelapp.py\", line 739, in start\n\n  File \"/Users/tupho/miniconda3/lib/python3.11/site-packages/tornado/platform/asyncio.py\", line 195, in start\n\n  File \"/Users/tupho/miniconda3/lib/python3.11/asyncio/base_events.py\", line 607, in run_forever\n\n  File \"/Users/tupho/miniconda3/lib/python3.11/asyncio/base_events.py\", line 1922, in _run_once\n\n  File \"/Users/tupho/miniconda3/lib/python3.11/asyncio/events.py\", line 80, in _run\n\n  File \"/Users/tupho/miniconda3/lib/python3.11/site-packages/ipykernel/kernelbase.py\", line 542, in dispatch_queue\n\n  File \"/Users/tupho/miniconda3/lib/python3.11/site-packages/ipykernel/kernelbase.py\", line 531, in process_one\n\n  File \"/Users/tupho/miniconda3/lib/python3.11/site-packages/ipykernel/kernelbase.py\", line 437, in dispatch_shell\n\n  File \"/Users/tupho/miniconda3/lib/python3.11/site-packages/ipykernel/ipkernel.py\", line 359, in execute_request\n\n  File \"/Users/tupho/miniconda3/lib/python3.11/site-packages/ipykernel/kernelbase.py\", line 775, in execute_request\n\n  File \"/Users/tupho/miniconda3/lib/python3.11/site-packages/ipykernel/ipkernel.py\", line 446, in do_execute\n\n  File \"/Users/tupho/miniconda3/lib/python3.11/site-packages/ipykernel/zmqshell.py\", line 549, in run_cell\n\n  File \"/Users/tupho/miniconda3/lib/python3.11/site-packages/IPython/core/interactiveshell.py\", line 3051, in run_cell\n\n  File \"/Users/tupho/miniconda3/lib/python3.11/site-packages/IPython/core/interactiveshell.py\", line 3106, in _run_cell\n\n  File \"/Users/tupho/miniconda3/lib/python3.11/site-packages/IPython/core/async_helpers.py\", line 129, in _pseudo_sync_runner\n\n  File \"/Users/tupho/miniconda3/lib/python3.11/site-packages/IPython/core/interactiveshell.py\", line 3311, in run_cell_async\n\n  File \"/Users/tupho/miniconda3/lib/python3.11/site-packages/IPython/core/interactiveshell.py\", line 3493, in run_ast_nodes\n\n  File \"/Users/tupho/miniconda3/lib/python3.11/site-packages/IPython/core/interactiveshell.py\", line 3553, in run_code\n\n  File \"/var/folders/30/wpb2n_hs72q5fz9yvp8c1cth0000gv/T/ipykernel_66003/644218478.py\", line 27, in <module>\n\n  File \"/Users/tupho/miniconda3/lib/python3.11/site-packages/keras_tuner/src/engine/base_tuner.py\", line 234, in search\n\n  File \"/Users/tupho/miniconda3/lib/python3.11/site-packages/keras_tuner/src/engine/base_tuner.py\", line 274, in _try_run_and_update_trial\n\n  File \"/Users/tupho/miniconda3/lib/python3.11/site-packages/keras_tuner/src/engine/base_tuner.py\", line 239, in _run_and_update_trial\n\n  File \"/Users/tupho/miniconda3/lib/python3.11/site-packages/keras_tuner/src/engine/tuner.py\", line 314, in run_trial\n\n  File \"/Users/tupho/miniconda3/lib/python3.11/site-packages/keras_tuner/src/engine/tuner.py\", line 233, in _build_and_fit_model\n\n  File \"/Users/tupho/miniconda3/lib/python3.11/site-packages/keras_tuner/src/engine/hypermodel.py\", line 149, in fit\n\n  File \"/Users/tupho/miniconda3/lib/python3.11/site-packages/keras/src/utils/traceback_utils.py\", line 117, in error_handler\n\n  File \"/Users/tupho/miniconda3/lib/python3.11/site-packages/keras/src/backend/tensorflow/trainer.py\", line 345, in fit\n\n  File \"/Users/tupho/miniconda3/lib/python3.11/site-packages/keras/src/utils/traceback_utils.py\", line 117, in error_handler\n\n  File \"/Users/tupho/miniconda3/lib/python3.11/site-packages/keras/src/backend/tensorflow/trainer.py\", line 433, in evaluate\n\n  File \"/Users/tupho/miniconda3/lib/python3.11/site-packages/keras/src/backend/tensorflow/trainer.py\", line 165, in one_step_on_iterator\n\n  File \"/Users/tupho/miniconda3/lib/python3.11/site-packages/keras/src/backend/tensorflow/trainer.py\", line 154, in one_step_on_data\n\n  File \"/Users/tupho/miniconda3/lib/python3.11/site-packages/keras/src/backend/tensorflow/trainer.py\", line 82, in test_step\n\n  File \"/Users/tupho/miniconda3/lib/python3.11/site-packages/keras/src/utils/traceback_utils.py\", line 117, in error_handler\n\n  File \"/Users/tupho/miniconda3/lib/python3.11/site-packages/keras/src/layers/layer.py\", line 901, in __call__\n\n  File \"/Users/tupho/miniconda3/lib/python3.11/site-packages/keras/src/utils/traceback_utils.py\", line 117, in error_handler\n\n  File \"/Users/tupho/miniconda3/lib/python3.11/site-packages/keras/src/ops/operation.py\", line 46, in __call__\n\n  File \"/Users/tupho/miniconda3/lib/python3.11/site-packages/keras/src/utils/traceback_utils.py\", line 156, in error_handler\n\n  File \"/Users/tupho/miniconda3/lib/python3.11/site-packages/keras/src/models/functional.py\", line 175, in call\n\n  File \"/Users/tupho/miniconda3/lib/python3.11/site-packages/keras/src/ops/function.py\", line 171, in _run_through_graph\n\n  File \"/Users/tupho/miniconda3/lib/python3.11/site-packages/keras/src/models/functional.py\", line 560, in call\n\n  File \"/Users/tupho/miniconda3/lib/python3.11/site-packages/keras/src/utils/traceback_utils.py\", line 117, in error_handler\n\n  File \"/Users/tupho/miniconda3/lib/python3.11/site-packages/keras/src/layers/layer.py\", line 901, in __call__\n\n  File \"/Users/tupho/miniconda3/lib/python3.11/site-packages/keras/src/utils/traceback_utils.py\", line 117, in error_handler\n\n  File \"/Users/tupho/miniconda3/lib/python3.11/site-packages/keras/src/ops/operation.py\", line 46, in __call__\n\n  File \"/Users/tupho/miniconda3/lib/python3.11/site-packages/keras/src/utils/traceback_utils.py\", line 156, in error_handler\n\n  File \"/Users/tupho/miniconda3/lib/python3.11/site-packages/keras/src/models/sequential.py\", line 212, in call\n\n  File \"/Users/tupho/miniconda3/lib/python3.11/site-packages/keras/src/models/functional.py\", line 175, in call\n\n  File \"/Users/tupho/miniconda3/lib/python3.11/site-packages/keras/src/ops/function.py\", line 171, in _run_through_graph\n\n  File \"/Users/tupho/miniconda3/lib/python3.11/site-packages/keras/src/models/functional.py\", line 560, in call\n\n  File \"/Users/tupho/miniconda3/lib/python3.11/site-packages/keras/src/utils/traceback_utils.py\", line 117, in error_handler\n\n  File \"/Users/tupho/miniconda3/lib/python3.11/site-packages/keras/src/layers/layer.py\", line 901, in __call__\n\n  File \"/Users/tupho/miniconda3/lib/python3.11/site-packages/keras/src/utils/traceback_utils.py\", line 117, in error_handler\n\n  File \"/Users/tupho/miniconda3/lib/python3.11/site-packages/keras/src/ops/operation.py\", line 46, in __call__\n\n  File \"/Users/tupho/miniconda3/lib/python3.11/site-packages/keras/src/utils/traceback_utils.py\", line 156, in error_handler\n\n  File \"/Users/tupho/miniconda3/lib/python3.11/site-packages/keras/src/layers/core/dense.py\", line 146, in call\n\n  File \"/Users/tupho/miniconda3/lib/python3.11/site-packages/keras/src/ops/numpy.py\", line 168, in add\n\n  File \"/Users/tupho/miniconda3/lib/python3.11/site-packages/keras/src/backend/tensorflow/sparse.py\", line 493, in sparse_wrapper\n\n  File \"/Users/tupho/miniconda3/lib/python3.11/site-packages/keras/src/backend/tensorflow/numpy.py\", line 38, in add\n\nIncompatible shapes: [0] vs. [947,40]\n\t [[{{node functional_18_1/X20_subnetwork_1/dense_96_1/Add}}]] [Op:__inference_one_step_on_iterator_195921]\n"}